<?xml version="1.0"?>
<sdf version='1.10'>
  <world name="xmate_world"> 
    <model name='xmate'>
      <joint name="panda_joint_world" type="fixed">
        <parent>world</parent>
        <child>base_link</child>
    </joint>
      <link name='base_link'>
        <inertial>
          <pose>-0.019088000000000001 4.4427e-05 0.06241 0 0 0</pose>
          <mass>3.1488</mass>
          <inertia>
            <ixx>0.011844</ixx>
            <ixy>2.9235999999999999e-05</ixy>
            <ixz>-0.0019436</ixz>
            <iyy>0.016485</iyy>
            <iyz>5.2961e-06</iyz>
            <izz>0.013575</izz>
          </inertia>
        </inertial>
        <collision name='base_link_collision'>
          <pose>0 0 0 0 0 0</pose>
          <geometry>
            <mesh>
              <scale>1 1 1</scale>
              <uri>meshes/base_link.STL</uri>
            </mesh>
          </geometry>
        </collision>
        <visual name='base_link_visual'>
          <pose>0 0 0 0 0 0</pose>
          <geometry>
            <mesh>
              <scale>1 1 1</scale>
              <uri>meshes/base_link.STL</uri>
            </mesh>
          </geometry>
          <material>
            <diffuse>0.740199983 0.833337545 0.85293746 1</diffuse>
            <ambient>0.740199983 0.833337545 0.85293746 1</ambient>
          </material>
        </visual>
      </link>
      <joint name='joint1' type='revolute'>
        <pose relative_to='base_link'>0 0 0.34150000000000003 0 0 0</pose>
        <parent>base_link</parent>
        <child>link1</child>
        <axis>
          <xyz>0 0 -1</xyz>
          <limit>
            <lower>-2.9670000000000001</lower>
            <upper>2.9670000000000001</upper>
            <effort>94</effort>
            <velocity>1.5708</velocity>
          </limit>
          <dynamics>
            <spring_reference>0</spring_reference>
            <spring_stiffness>0</spring_stiffness>
          </dynamics>
        </axis>
      </joint>
      <link name='link1'>
        <pose relative_to='joint1'>0 0 0 0 0 0</pose>
        <inertial>
          <pose>3.7179999999999998e-06 -0.025274000000000001 -0.053443999999999998 0 0 0</pose>
          <mass>1.8005</mass>
          <inertia>
            <ixx>0.0095697999999999998</ixx>
            <ixy>-6.8655999999999998e-07</ixy>
            <ixz>-4.8250000000000004e-07</ixz>
            <iyy>0.0085643000000000004</iyy>
            <iyz>0.0019572999999999999</iyz>
            <izz>0.0033056000000000001</izz>
          </inertia>
        </inertial>
        <collision name='link1_collision'>
          <pose>0 0 0 0 0 0</pose>
          <geometry>
            <mesh>
              <scale>1 1 1</scale>
              <uri>meshes/link1.STL</uri>
            </mesh>
          </geometry>
        </collision>
        <visual name='link1_visual'>
          <pose>0 0 0 0 0 0</pose>
          <geometry>
            <mesh>
              <scale>1 1 1</scale>
              <uri>meshes/link1.STL</uri>
            </mesh>
          </geometry>
          <material>
            <diffuse>0.740199983 0.833337545 0.85293746 1</diffuse>
            <ambient>0.740199983 0.833337545 0.85293746 1</ambient>
          </material>
        </visual>
      </link>
      <joint name='joint2' type='revolute'>
        <pose relative_to='link1'>0 0 0 1.5708 0 0</pose>
        <parent>link1</parent>
        <child>link2</child>
        <axis>
          <xyz>0 0 1</xyz>
          <limit>
            <lower>-2.0939999999999999</lower>
            <upper>2.0939999999999999</upper>
            <effort>110</effort>
            <velocity>1.5708</velocity>
          </limit>
          <dynamics>
            <spring_reference>0</spring_reference>
            <spring_stiffness>0</spring_stiffness>
          </dynamics>
        </axis>
      </joint>
      <link name='link2'>
        <pose relative_to='joint2'>0 0 0 0 0 0</pose>
        <inertial>
          <pose>-6.1017000000000004e-06 0.094687999999999994 -0.027636000000000001 0 0 0</pose>
          <mass>2.1852999999999998</mass>
          <inertia>
            <ixx>0.017961000000000001</ixx>
            <ixy>-2.0946e-07</ixy>
            <ixz>-7.2091000000000001e-07</ixz>
            <iyy>0.0044672999999999996</iyy>
            <iyz>-0.0045671000000000002</iyz>
            <izz>0.016295</izz>
          </inertia>
        </inertial>
        <collision name='link2_collision'>
          <pose>0 0 0 0 0 0</pose>
          <geometry>
            <mesh>
              <scale>1 1 1</scale>
              <uri>meshes/link2.STL</uri>
            </mesh>
          </geometry>
        </collision>
        <visual name='link2_visual'>
          <pose>0 0 0 0 0 0</pose>
          <geometry>
            <mesh>
              <scale>1 1 1</scale>
              <uri>meshes/link2.STL</uri>
            </mesh>
          </geometry>
          <material>
            <diffuse>0.740199983 0.833337545 0.85293746 1</diffuse>
            <ambient>0.740199983 0.833337545 0.85293746 1</ambient>
          </material>
        </visual>
      </link>
      <joint name='joint3' type='revolute'>
        <pose relative_to='link2'>0 0.39399990552675401 0 -1.5707921336170201 0 0</pose>
        <parent>link2</parent>
        <child>link3</child>
        <axis>
          <xyz>0 0 -0.99999999999992595</xyz>
          <limit>
            <lower>-2.9670000000000001</lower>
            <upper>2.9670000000000001</upper>
            <effort>94</effort>
            <velocity>1.5708</velocity>
          </limit>
          <dynamics>
            <spring_reference>0</spring_reference>
            <spring_stiffness>0</spring_stiffness>
          </dynamics>
        </axis>
      </joint>
      <link name='link3'>
        <pose relative_to='joint3'>0 0 0 0 0 0</pose>
        <inertial>
          <pose>2.1156000000000001e-06 -0.025028000000000002 -0.053620000000000001 0 0 0</pose>
          <mass>1.7944</mass>
          <inertia>
            <ixx>0.0095218999999999998</ixx>
            <ixy>-6.2641000000000001e-07</ixy>
            <ixz>-6.1200000000000003e-07</ixz>
            <iyy>0.0085457999999999992</iyy>
            <iyz>0.0019369000000000001</iyz>
            <izz>0.0032759999999999998</izz>
          </inertia>
        </inertial>
        <collision name='link3_collision'>
          <pose>0 0 0 0 0 0</pose>
          <geometry>
            <mesh>
              <scale>1 1 1</scale>
              <uri>meshes/link3.STL</uri>
            </mesh>
          </geometry>
        </collision>
        <visual name='link3_visual'>
          <pose>0 0 0 0 0 0</pose>
          <geometry>
            <mesh>
              <scale>1 1 1</scale>
              <uri>meshes/link3.STL</uri>
            </mesh>
          </geometry>
          <material>
            <diffuse>0.740199983 0.833337545 0.85293746 1</diffuse>
            <ambient>0.740199983 0.833337545 0.85293746 1</ambient>
          </material>
        </visual>
      </link>
      <joint name='joint4' type='revolute'>
        <pose relative_to='link3'>0 0 0 1.5707967678663599 0 0</pose>
        <parent>link3</parent>
        <child>link4</child>
        <axis>
          <xyz>0 0 1</xyz>
          <limit>
            <lower>-2.0939999999999999</lower>
            <upper>2.0939999999999999</upper>
            <effort>94</effort>
            <velocity>1.5708</velocity>
          </limit>
          <dynamics>
            <spring_reference>0</spring_reference>
            <spring_stiffness>0</spring_stiffness>
          </dynamics>
        </axis>
      </joint>
      <link name='link4'>
        <pose relative_to='joint4'>0 0 0 0 0 0</pose>
        <inertial>
          <pose>3.4697999999999998e-06 0.075813000000000005 -0.032772999999999997 0 0 0</pose>
          <mass>1.7968</mass>
          <inertia>
            <ixx>0.013063999999999999</ixx>
            <ixy>-8.1017999999999997e-07</ixy>
            <ixz>-2.1089e-07</ixz>
            <iyy>0.0033492000000000001</iyy>
            <iyz>-0.0034602000000000001</iyz>
            <izz>0.011734</izz>
          </inertia>
        </inertial>
        <collision name='link4_collision'>
          <pose>0 0 0 0 0 0</pose>
          <geometry>
            <mesh>
              <scale>1 1 1</scale>
              <uri>meshes/link4.STL</uri>
            </mesh>
          </geometry>
        </collision>
        <visual name='link4_visual'>
          <pose>0 0 0 0 0 0</pose>
          <geometry>
            <mesh>
              <scale>1 1 1</scale>
              <uri>meshes/link4.STL</uri>
            </mesh>
          </geometry>
          <material>
            <diffuse>0.740199983 0.833337545 0.85293746 1</diffuse>
            <ambient>0.740199983 0.833337545 0.85293746 1</ambient>
          </material>
        </visual>
      </link>
      <joint name='joint5' type='revolute'>
        <pose relative_to='link4'>0 0.36599999999999999 0 -1.5708 0 0</pose>
        <parent>link4</parent>
        <child>link5</child>
        <axis>
          <xyz>0 0 -1</xyz>
          <limit>
            <lower>-2.9670000000000001</lower>
            <upper>2.9670000000000001</upper>
            <effort>29</effort>
            <velocity>1.9624999999999999</velocity>
          </limit>
          <dynamics>
            <spring_reference>0</spring_reference>
            <spring_stiffness>0</spring_stiffness>
          </dynamics>
        </axis>
      </joint>
      <link name='link5'>
        <pose relative_to='joint5'>0 0 0 0 0 0</pose>
        <inertial>
          <pose>1.21714844333112e-05 -0.031276169623672002 -0.045700606921044197 0 0 0</pose>
          <mass>1.2958128243652101</mass>
          <inertia>
            <ixx>0.0059855193315267096</ixx>
            <ixy>-4.76355081923921e-07</ixy>
            <ixz>5.4571642264800105e-07</ixz>
            <iyy>0.00489832818590761</iyy>
            <iyz>0.00152655463457091</iyz>
            <izz>0.00226748492439003</izz>
          </inertia>
        </inertial>
        <collision name='link5_collision'>
          <pose>0 0 0 0 0 0</pose>
          <geometry>
            <mesh>
              <scale>1 1 1</scale>
              <uri>meshes/link5.STL</uri>
            </mesh>
          </geometry>
        </collision>
        <visual name='link5_visual'>
          <pose>0 0 0 0 0 0</pose>
          <geometry>
            <mesh>
              <scale>1 1 1</scale>
              <uri>meshes/link5.STL</uri>
            </mesh>
          </geometry>
          <material>
            <diffuse>0.740196109 0.833333373 0.852941215 1</diffuse>
            <ambient>0.740196109 0.833333373 0.852941215 1</ambient>
          </material>
        </visual>
      </link>
      <joint name='joint6' type='revolute'>
        <pose relative_to='link5'>0 0 0 1.5707963267949003 0 0</pose>
        <parent>link5</parent>
        <child>link6</child>
        <axis>
          <xyz>0 0 1</xyz>
          <limit>
            <lower>-2.0939999999999999</lower>
            <upper>2.0939999999999999</upper>
            <effort>29</effort>
            <velocity>1.9624999999999999</velocity>
          </limit>
          <dynamics>
            <spring_reference>0</spring_reference>
            <spring_stiffness>0</spring_stiffness>
          </dynamics>
        </axis>
      </joint>
      <link name='link6'>
        <pose relative_to='joint6'>0 0 0 0 0 0</pose>
        <inertial>
          <pose>1.2826000000000001e-05 0.084293999999999994 -0.015148999999999999 0 0 0</pose>
          <mass>1.2251000000000001</mass>
          <inertia>
            <ixx>0.0062840999999999999</ixx>
            <ixy>3.4424999999999998e-07</ixy>
            <ixz>1.1226e-07</ixz>
            <iyy>0.0014649000000000001</iyy>
            <iyz>-0.0012842000000000001</iyz>
            <izz>0.0059858000000000003</izz>
          </inertia>
        </inertial>
        <collision name='link6_collision'>
          <pose>0 0 0 0 0 0</pose>
          <geometry>
            <mesh>
              <scale>1 1 1</scale>
              <uri>meshes/link6.STL</uri>
            </mesh>
          </geometry>
        </collision>
        <visual name='link6_visual'>
          <pose>0 0 0 0 0 0</pose>
          <geometry>
            <mesh>
              <scale>1 1 1</scale>
              <uri>meshes/link6.STL</uri>
            </mesh>
          </geometry>
          <material>
            <diffuse>0.740199983 0.833337545 0.85293746 1</diffuse>
            <ambient>0.740199983 0.833337545 0.85293746 1</ambient>
          </material>
        </visual>
      </link>
      <joint name='joint7' type='revolute'>
        <pose relative_to='link6'>0 0.25029999994029001 0.00038204393466717502 -1.5707963267949003 0 0</pose>
        <parent>link6</parent>
        <child>link7</child>
        <axis>
          <xyz>0 0 -1</xyz>
          <limit>
            <lower>-6.2800000000000002</lower>
            <upper>6.2800000000000002</upper>
            <effort>29</effort>
            <velocity>1.9624999999999999</velocity>
          </limit>
          <dynamics>
            <spring_reference>0</spring_reference>
            <spring_stiffness>0</spring_stiffness>
          </dynamics>
        </axis>
      </joint>
      <link name='link7'>
        <pose relative_to='joint7'>0 0 0 0 0 0</pose>
        <inertial>
          <pose>3.1180000000000003e-05 0.019817999999999999 -0.027775000000000001 0 0 0</pose>
          <mass>0.64405000000000001</mass>
          <inertia>
            <ixx>0.0013047</ixx>
            <ixy>-2.2980000000000001e-07</ixy>
            <ixz>-6.1879000000000005e-07</ixz>
            <iyy>0.00079066</iyy>
            <iyz>0.00027873999999999998</iyz>
            <izz>0.0009789</izz>
          </inertia>
        </inertial>
        <collision name='link7_collision'>
          <pose>0 0 0 0 0 0</pose>
          <geometry>
            <mesh>
              <scale>1 1 1</scale>
              <uri>meshes/link7.STL</uri>
            </mesh>
          </geometry>
        </collision>
        <visual name='link7_visual'>
          <pose>0 0 0 0 0 0</pose>
          <geometry>
            <mesh>
              <scale>1 1 1</scale>
              <uri>meshes/link7.STL</uri>
            </mesh>
          </geometry>
          <material>
            <diffuse>0.740199983 0.833337545 0.85293746 1</diffuse>
            <ambient>0.740199983 0.833337545 0.85293746 1</ambient>
          </material>
        </visual>
      </link>
      <plugin filename="ignition-gazebo-joint-position-controller-system" name="ignition::gazebo::systems::JointPositionController">
          <joint_name>joint1</joint_name>
          <p_gain>100</p_gain>
          <d_gain>50</d_gain>
          <i_gain>0</i_gain>
          <i_min>-1</i_min>
          <i_max>1</i_max>
          <cmd_min>-120</cmd_min>
          <cmd_max>120</cmd_max>
      </plugin>
      <plugin filename="ignition-gazebo-joint-position-controller-system" name="ignition::gazebo::systems::JointPositionController">
          <joint_name>joint2</joint_name>
          <p_gain>100</p_gain>
          <d_gain>50</d_gain>
          <i_gain>0</i_gain>
          <i_min>-1</i_min>
          <i_max>1</i_max>
          <cmd_min>-120</cmd_min>
          <cmd_max>120</cmd_max>
      </plugin>
      <plugin filename="ignition-gazebo-joint-position-controller-system" name="ignition::gazebo::systems::JointPositionController">
          <joint_name>joint3</joint_name>
          <p_gain>100</p_gain>
          <d_gain>50</d_gain>
          <i_gain>0</i_gain>
          <i_min>-1</i_min>
          <i_max>1</i_max>
          <cmd_min>-120</cmd_min>
          <cmd_max>120</cmd_max>
      </plugin>
      <plugin filename="ignition-gazebo-joint-position-controller-system" name="ignition::gazebo::systems::JointPositionController">
          <joint_name>joint4</joint_name>
          <p_gain>100</p_gain>
          <d_gain>50</d_gain>
          <i_gain>0</i_gain>
          <i_min>-1</i_min>
          <i_max>1</i_max>
          <cmd_min>-120</cmd_min>
          <cmd_max>120</cmd_max>
      </plugin>
      <plugin filename="ignition-gazebo-joint-position-controller-system" name="ignition::gazebo::systems::JointPositionController">
          <joint_name>joint5</joint_name>
          <p_gain>100</p_gain>
          <d_gain>50</d_gain>
          <i_gain>0</i_gain>
          <i_min>-1</i_min>
          <i_max>1</i_max>
          <cmd_min>-120</cmd_min>
          <cmd_max>120</cmd_max>
      </plugin>
      <plugin filename="ignition-gazebo-joint-position-controller-system" name="ignition::gazebo::systems::JointPositionController">
        <joint_name>joint6</joint_name>
        <p_gain>100</p_gain>
        <d_gain>50</d_gain>
        <i_gain>0</i_gain>
        <i_min>-1</i_min>
        <i_max>1</i_max>
        <cmd_min>-12</cmd_min>
        <cmd_max>12</cmd_max>
      </plugin>
      <plugin filename="ignition-gazebo-joint-position-controller-system" name="ignition::gazebo::systems::JointPositionController">
        <joint_name>joint7</joint_name>
        <p_gain>100</p_gain>
        <d_gain>50</d_gain>
        <i_gain>0</i_gain>
        <i_min>-1</i_min>
        <i_max>1</i_max>
        <cmd_min>-12</cmd_min>
        <cmd_max>12</cmd_max>
      </plugin>
    </model>
  </world>
</sdf>
